{
    "timestamp": "2025-01-10T17:05:22.934367",
    "level": "INFO",
    "message": "Exiting the programm",
    "module": "LoggerFormatter",
    "line_number": 16
}
{
    "timestamp": "2025-01-10T17:05:22.935366",
    "level": "INFO",
    "message": "Application finished successfully",
    "module": "LoggerFormatter",
    "line_number": 16
}
{
    "timestamp": "2025-01-10T17:05:32.230908",
    "level": "INFO",
    "message": "Application started",
    "module": "LoggerFormatter",
    "line_number": 16
}
{
    "timestamp": "2025-01-10T17:05:35.595106",
    "level": "INFO",
    "message": "Run tests",
    "module": "LoggerFormatter",
    "line_number": 16
}
{
    "timestamp": "2025-01-10T17:05:35.596115",
    "level": "ERROR",
    "message": "Test error: Invalid value detected!",
    "module": "LoggerFormatter",
    "line_number": 22,
    "exception": [
        "Traceback (most recent call last):",
        "  File \"d:\\DmytroMarkin\\Programming\\TestModule.py\", line 10, in run_tests",
        "    raise ValueError(\"Test error: Invalid value detected!\")",
        "ValueError: Test error: Invalid value detected!"
    ]
}
{
    "timestamp": "2025-01-10T17:05:35.628734",
    "level": "CRITICAL",
    "message": "Failed to send error email: [Errno 11001] getaddrinfo failed",
    "module": "LoggerFormatter",
    "line_number": 25,
    "exception": [
        "Traceback (most recent call last):",
        "  File \"d:\\DmytroMarkin\\Programming\\TestModule.py\", line 10, in run_tests",
        "    raise ValueError(\"Test error: Invalid value detected!\")",
        "ValueError: Test error: Invalid value detected!",
        "",
        "During handling of the above exception, another exception occurred:",
        "",
        "Traceback (most recent call last):",
        "  File \"d:\\DmytroMarkin\\Programming\\ErrorHandler.py\", line 18, in send_error_email",
        "    server = smtplib.SMTP(self.email_settings[\"smtp_server\"], self.email_settings[\"smtp_port\"])",
        "             ^^^^^^^^^^^^^^^^^^^^^^^^^^^^^^^^^^^^^^^^^^^^^^^^^^^^^^^^^^^^^^^^^^^^^^^^^^^^^^^^^^",
        "  File \"C:\\Users\\1\\AppData\\Local\\Programs\\Python\\Python312\\Lib\\smtplib.py\", line 255, in __init__",
        "    (code, msg) = self.connect(host, port)",
        "                  ^^^^^^^^^^^^^^^^^^^^^^^^",
        "  File \"C:\\Users\\1\\AppData\\Local\\Programs\\Python\\Python312\\Lib\\smtplib.py\", line 341, in connect",
        "    self.sock = self._get_socket(host, port, self.timeout)",
        "                ^^^^^^^^^^^^^^^^^^^^^^^^^^^^^^^^^^^^^^^^^^",
        "  File \"C:\\Users\\1\\AppData\\Local\\Programs\\Python\\Python312\\Lib\\smtplib.py\", line 312, in _get_socket",
        "    return socket.create_connection((host, port), timeout,",
        "           ^^^^^^^^^^^^^^^^^^^^^^^^^^^^^^^^^^^^^^^^^^^^^^^",
        "  File \"C:\\Users\\1\\AppData\\Local\\Programs\\Python\\Python312\\Lib\\socket.py\", line 841, in create_connection",
        "    for res in getaddrinfo(host, port, 0, SOCK_STREAM):",
        "               ^^^^^^^^^^^^^^^^^^^^^^^^^^^^^^^^^^^^^^^",
        "  File \"C:\\Users\\1\\AppData\\Local\\Programs\\Python\\Python312\\Lib\\socket.py\", line 976, in getaddrinfo",
        "    for res in _socket.getaddrinfo(host, port, family, type, proto, flags):",
        "               ^^^^^^^^^^^^^^^^^^^^^^^^^^^^^^^^^^^^^^^^^^^^^^^^^^^^^^^^^^^",
        "socket.gaierror: [Errno 11001] getaddrinfo failed"
    ]
}
{
    "timestamp": "2025-01-10T17:06:54.128609",
    "level": "INFO",
    "message": "Exiting the programm",
    "module": "LoggerFormatter",
    "line_number": 16
}
{
    "timestamp": "2025-01-10T17:06:54.128609",
    "level": "INFO",
    "message": "Application finished successfully",
    "module": "LoggerFormatter",
    "line_number": 16
}
